<?xml version="1.0"?>

<robot xmlns:xacro="http://ros.org/wiki/xacro"> 
  <xacro:macro name="actuated_wheel" params="prefix locationprefix locationright damping_wheel friction_wheel">
    <joint name="${prefix}${locationprefix}_wheel_joint" type="continuous">
      <origin xyz="0.0 ${-mir_200_act_wheel_dy * locationright} ${mir_200_act_wheel_radius}" rpy="0 0 0" />
      <parent link="${prefix}base_link" />
      <child link="${prefix}${locationprefix}_wheel_link" />
      <axis xyz="0 1 0" />
      <limit effort="200" velocity="20.0" />
      <dynamics damping="${damping_wheel}" friction="${friction_wheel}"/>
    </joint>

    <link name="${prefix}${locationprefix}_wheel_link">
      <xacro:cylinder_inertial mass="${mir_200_act_wheel_mass}" radius="${mir_200_act_wheel_radius}" length="${mir_200_act_wheel_width}">
        <origin xyz="0 0 0" rpy="${0.5 * pi} 0 0" />
      </xacro:cylinder_inertial>
      <visual>
        <origin xyz="0 0 0" rpy="0 0 0" />
        <geometry>
          <mesh filename="package://mir_description/meshes/visual/wheel.stl" />
        </geometry>
        <xacro:insert_block name="material_dark_grey" />
      </visual>
      <collision>
        <origin xyz="0 0 0" rpy="0 0 0" />
        <geometry>
          <mesh filename="package://mir_description/meshes/visual/wheel.stl" />
        </geometry>
        <surface>
          <friction>
            <mu1 value="10.0"/>
            <mu2 value="0.0"/>
          </friction> 
      </surface>
      </collision>
      

    </link>
    <gazebo reference="${prefix}${locationprefix}_wheel_link">
      <material>Gazebo/DarkGrey</material>
    </gazebo>
  </xacro:macro>
</robot>