<?xml version="1.0"?>

<robot xmlns:xacro="http://ros.org/wiki/xacro">
    <xacro:macro name="caster_wheel" params="prefix locationprefix locationright wheel_base_dx damping_steering friction_steering damping_wheel friction_wheel">
        <!-- caster hub -->
        <joint name="${prefix}${locationprefix}_caster_rotation_joint" type="continuous">
            <origin xyz="${wheel_base_dx} ${-mir_200_caster_wheel_base_dy * locationright} ${mir_200_caster_wheel_base_dz}" rpy="0 0 0" />
            <parent link="${prefix}base_link" />
            <child link="${prefix}${locationprefix}_caster_rotation_link" />
            <axis xyz="0 0 1" />
            <dynamics damping="${damping_steering}" friction="${friction_steering}"/>
        </joint>

        <link name="${prefix}${locationprefix}_caster_rotation_link">
            <inertial>
                <!-- <origin xyz="0 0 -0.042500000044" rpy="${0.5 * pi} ${24 * deg_to_rad} ${1.5 * pi}" /> -->
                <origin xyz="0 0 -0.042500000044" rpy="${24 * deg_to_rad} 0 ${0.5 * pi} " />
                <mass value="0.3097539019" />
                <inertia
                ixx="0.0005844517978"
                ixy="0"
                ixz="0"
                iyy="0.00052872551237"
                iyz="0"
                izz="0.00017923555074" />
            </inertial>
            <visual>
                <origin xyz="0 0 0" rpy="0 0 0" />
                <geometry>
                <mesh filename="package://mir_description/meshes/visual/caster_wheel_base.stl" />
                </geometry>
                <xacro:insert_block name="material_silver" />
            </visual>
            <collision>
                <origin xyz="0 0 0" rpy="0 0 0" />
                <geometry>
                <mesh filename="package://mir_description/meshes/collision/caster_wheel_base.stl" />
                </geometry>
            </collision>
        </link>

        <gazebo reference="${prefix}${locationprefix}_caster_rotation_link">
        <material>Gazebo/Grey</material>
        </gazebo>

        <!-- caster wheel -->
        <joint name="${prefix}${locationprefix}_caster_wheel_joint" type="continuous">
            <origin xyz="${mir_200_caster_wheel_dx} ${-mir_200_caster_wheel_dy * locationright} ${mir_200_caster_wheel_dz}" rpy="0 0 0" />
            <parent link="${prefix}${locationprefix}_caster_rotation_link" />
            <child link="${prefix}${locationprefix}_caster_wheel_link" />
            <axis xyz="0 1 0" />
            <dynamics damping="${damping_wheel}" friction="${friction_wheel}"/>
        </joint>

        <link name="${prefix}${locationprefix}_caster_wheel_link">
            <xacro:cylinder_inertial mass="${mir_200_caster_wheel_mass}" radius="${mir_200_caster_wheel_radius}" length="${mir_200_caster_wheel_width}">
                <origin xyz="0 0 0" rpy="${0.5 * pi} 0 0" />
            </xacro:cylinder_inertial>
            <visual>
                <origin xyz="0 0 0" rpy="0 0 0" />
                <geometry>
                <mesh filename="package://mir_description/meshes/visual/wheel.stl" />
                </geometry>
                <xacro:insert_block name="material_dark_grey" />
            </visual>
            <collision  >
                <origin xyz="0 0 0" rpy="0 0 0" />
                <geometry>
                    <mesh filename="package://mir_description/meshes/visual/wheel.stl" />
                </geometry>
            </collision>
        </link>
        <gazebo reference="${prefix}${locationprefix}_caster_wheel_link">
        <material>Gazebo/DarkGrey</material>
        </gazebo>
        </xacro:macro>
</robot>